<robot name="dji_gimbal">
  <link name="base_link" />
  <link name="gimbal_base/yaw" />
  <link name="gimbal_base/roll" />
  <link name="gimbal_base/pitch" />
  <link name="gimbal_base/camera" />

  <joint name="yaw" type="continuous">
    <parent link="base_link"/>
    <child link="gimbal_base/yaw"/>
    <origin xyz="0.11 0 0" rpy="0 0 0" />
    <axis xyz="0 0 -1" />
  </joint>

  <joint name="roll" type="continuous">
    <parent link="gimbal_base/yaw"/>
    <child link="gimbal_base/roll"/>
    <origin xyz="-0.0508 0 -0.08195" rpy="0 0 0" />
    <axis xyz="1 0 0" />
  </joint>

  <joint name="pitch" type="continuous">
    <parent link="gimbal_base/roll"/>
    <child link="gimbal_base/pitch"/>
    <origin xyz="0.068 -0.039 0" rpy="0 0 0" />
    <axis xyz="0 -1 0" />
  </joint>

  <joint name="camera_fixed" type="fixed">
    <parent link="gimbal_base/pitch"/>
    <child link="gimbal_base/camera"/>
    <origin xyz="0 0.05 0" rpy="0 0 0" />
  </joint>

</robot>